<mujoco>
  <asset>
    <mesh name="base_link_collision" file="base_link_collision.STL"/>
    <mesh name="r_wheel_link_collision" file="r_wheel_link_collision.STL"/>
    <mesh name="l_wheel_link_collision" file="l_wheel_link_collision.STL"/>
    <mesh name="torso_lift_link_collision" file="torso_lift_link_collision.STL"/>
    <mesh name="head_pan_link_collision" file="head_pan_link_collision.STL"/>
    <mesh name="head_tilt_link_collision" file="head_tilt_link_collision.STL"/>
    <mesh name="shoulder_pan_link_collision" file="shoulder_pan_link_collision.STL"/>
    <mesh name="shoulder_lift_link_collision" file="shoulder_lift_link_collision.STL"/>
    <mesh name="upperarm_roll_link_collision" file="upperarm_roll_link_collision.STL"/>
    <mesh name="elbow_flex_link_collision" file="elbow_flex_link_collision.STL"/>
    <mesh name="forearm_roll_link_collision" file="forearm_roll_link_collision.STL"/>
    <mesh name="wrist_flex_link_collision" file="wrist_flex_link_collision.STL"/>
    <mesh name="wrist_roll_link_collision" file="wrist_roll_link_collision.STL"/>
    <mesh name="gripper_link" file="gripper_link.STL"/>
    <mesh name="r_gripper_finger_link" file="r_gripper_finger_link.STL"/>
    <mesh name="l_gripper_finger_link" file="l_gripper_finger_link.STL"/>
    <mesh name="bellows_link_collision" file="bellows_link_collision.STL"/>
    <mesh name="estop_link" file="estop_link.STL"/>
    <mesh name="laser_link" file="laser_link.STL"/>
    <mesh name="torso_fixed_link" file="torso_fixed_link.STL"/>
  </asset>
  <!-- Only missing bellows_joint2, its unnecessary in my circumstance -->
  <body name="base_link" pos="0 0 0">
    <geom type="mesh" rgba="0.356 0.361 0.376 1" mesh="base_link_collision"/>
    <geom pos="-0.12465 0.23892 0.31127" quat="0.707105 0.707108 0 0" type="mesh" rgba="0.8 0 0 1" mesh="estop_link"/>
    <geom pos="0.235 0 0.2878" quat="0 1 0 0" type="mesh" rgba="0.792157 0.819608 0.933333 1" mesh="laser_link"/>
    <geom pos="-0.086875 0 0.377425" type="mesh" rgba="0.086 0.506 0.767 1" mesh="torso_fixed_link"/>
    <body name="r_wheel_link" pos="0.0012914 -0.18738 0.055325" gravcomp="0">
      <inertial pos="0 0 0" quat="0.707107 0 0 0.707107" mass="4.3542" diaginertia="0.005 0.0045 0.0045"/>
      <joint name="r_wheel_joint" pos="0 0 0" axis="0 1 0"/>
      <geom type="mesh" rgba="0.086 0.506 0.767 1" mesh="r_wheel_link_collision"/>
    </body>
    <body name="l_wheel_link" pos="0.0012914 0.18738 0.055325" gravcomp="0">
      <inertial pos="0 0 0" quat="0.707107 0 0 0.707107" mass="4.3542" diaginertia="0.005 0.0045 0.0045"/>
      <joint name="l_wheel_joint" pos="0 0 0" axis="0 1 0"/>
      <geom type="mesh" rgba="0.086 0.506 0.767 1" mesh="l_wheel_link_collision"/>
    </body>
    <body name="torso_lift_link" pos="-0.086875 0 0.37743" gravcomp="0">
      <inertial pos="-0.000983929 -0.000886078 0.286874" quat="0.99962 -0.000833361 0.0269789 0.00565622" mass="10.949" diaginertia="0.370106 0.367813 0.0963668"/>
      <joint name="torso_lift_joint" pos="0 0 0" axis="0 0 1" type="slide" range="0 0.38615" damping="100"/>
      <geom type="mesh" rgba="1 1 1 1" mesh="torso_lift_link_collision"/>
      <geom type="mesh" rgba="0 0 0 1" mesh="bellows_link_collision"/>
      <body name="head_pan_link" pos="0.053125 0 0.603001" gravcomp="0">
        <inertial pos="0.0321 0.0161 0.039" quat="0.514814 0.545129 -0.452957 0.482318" mass="2.2556" diaginertia="0.0184878 0.0128242 0.00948808"/>
        <joint name="head_pan_joint" pos="0 0 0" axis="0 0 1" range="-1.57 1.57"/>
        <geom type="mesh" rgba="0.356 0.361 0.376 1" mesh="head_pan_link_collision"/>
        <body name="head_tilt_link" pos="0.14253 0 0.057999" gravcomp="0">
          <inertial pos="0.0081 0.0025 0.0113" quat="0.645806 0.659961 -0.274048 0.268857" mass="0.9087" diaginertia="0.00630102 0.00590111 0.00139787"/>
          <joint name="head_tilt_joint" pos="0 0 0" axis="0 1 0" range="-0.76 1.45"/>
          <geom type="mesh" rgba="0.086 0.506 0.767 1" mesh="head_tilt_link_collision"/>
          <!-- Additions -->
            <body name="head_camera_link" pos="0.055 0 0.0225">
              <inertial pos="0.055 0 0.0225" mass="0" diaginertia="0 0 0" />
              <body name="head_camera_rgb_frame" pos="0 0.02 0">
                <inertial  mass="0" pos="0 0.02 0" diaginertia="0 0 0"/>
                <body name="head_camera_rgb_optical_frame" pos="0 0 0" quat="0.5 -0.5 0.5 -0.5">
                  <inertial pos="0 0 0" quat="0.5 -0.5 0.5 -0.5" mass="0" diaginertia="0 0 0"/>
                  <camera name="head_camera_rgb" pos="0 0 0" euler="3.1415 0 0" fovy="50"></camera>
                </body>
              </body>
              <body name="head_camera_depth_frame" pos="0 0.045 0">
                <inertial pos="0 0.045 0" mass="0" diaginertia="0 0 0"/>
                <body name="head_camera_depth_optical_frame" pos="0 0 0" quat="0.5 -0.5 0.5 -0.5">
                  <inertial pos="0 0 0" quat="0.5 -0.5 0.5 -0.5" mass="0" diaginertia="0 0 0" ></inertial>
                </body>
              </body>
            </body>
          <!--  -->
        </body>
      </body>
      <body name="shoulder_pan_link" pos="0.119525 0 0.34858" gravcomp="0">
        <inertial pos="0.0927 -0.0056 0.0564" quat="-0.136432 0.762398 -0.156155 0.612985" mass="2.5587" diaginertia="0.00896934 0.00864854 0.00408212"/>
        <joint name="robot:joint1" pos="0 0 0" axis="0 0 1" range="-1.6056 1.6056" damping="1"/>
        <geom type="mesh" rgba="1 1 1 1" mesh="shoulder_pan_link_collision"/>
        <body name="shoulder_lift_link" pos="0.117 0 0.06" gravcomp="0">
          <inertial pos="0.1432 0.0072 -0.0001" quat="0.438152 0.438152 0.554998 0.554998" mass="2.6615" diaginertia="0.0116011 0.0112 0.00229892"/>
          <joint name="robot:joint2" pos="0 0 0" axis="0 1 0" range="-1.221 1.518" damping="1"/>
          <geom type="mesh" rgba="0.086 0.506 0.767 1" mesh="shoulder_lift_link_collision"/>
          <body name="upperarm_roll_link" pos="0.219 0 0" gravcomp="0">
            <inertial pos="0.1165 0.0014 0" quat="-0.0135706 0.706977 0.0135706 0.706977" mass="2.3311" diaginertia="0.0047 0.00450384 0.00189616"/>
            <joint name="urobot:joint3" pos="0 0 0" axis="1 0 0" range="-1000 1000" damping="5"/>
            <geom type="mesh" rgba="1 1 1 1" mesh="upperarm_roll_link_collision"/>
            <body name="elbow_flex_link" pos="0.133 0 0" gravcomp="0">
              <inertial pos="0.1279 0.0073 0" quat="0.43318 0.43318 0.558888 0.558888" mass="2.1299" diaginertia="0.0086121 0.0084 0.0019879"/>
              <joint name="robot:joint4" pos="0 0 0" axis="0 1 0" range="-2.251 2.251" damping="1"/>
              <geom type="mesh" rgba="0.086 0.506 0.767 1" mesh="elbow_flex_link_collision"/>
              <body name="forearm_roll_link" pos="0.197 0 0" gravcomp="0">
                <inertial pos="0.1097 -0.0266 0" quat="-0.0714533 0.703487 0.0714533 0.703487" mass="1.6563" diaginertia="0.0035 0.00306158 0.00153842"/>
                <joint name="robot:joint5" pos="0 0 0" axis="1 0 0" range="-1000 1000" damping="5"/>
                <geom type="mesh" rgba="1 1 1 1" mesh="forearm_roll_link_collision"/>
                <body name="wrist_flex_link" pos="0.1245 0 0" gravcomp="0">
                  <inertial pos="0.0882 0.0009 -0.0001" quat="0.4895 0.4895 0.510284 0.510284" mass="1.725" diaginertia="0.00420416 0.0042 0.00179584"/>
                  <joint name="robot:joint6" pos="0 0 0" axis="0 1 0" range="-2.16 2.16" damping="1"/>
                  <geom type="mesh" rgba="0.086 0.506 0.767 1" mesh="wrist_flex_link_collision"/>
                  <body name="wrist_roll_link" pos="0.1385 0 0" gravcomp="0">
                    <inertial pos="0.0709657 -5.90417e-05 -0.00157713" quat="0.00123263 0.709764 -0.00131059 0.704437" mass="1.6529" diaginertia="0.00305731 0.00255748 0.0014002"/>
                    <joint name="robot:joint7" pos="0 0 0" axis="1 0 0" range="-1000 1000" damping="5"/>
                    <geom type="mesh" rgba="1 1 1 1" mesh="wrist_roll_link_collision"/>
                    <!-- Additions -->
                    <body name="gripper_link" pos="0.16645 0 0">
                      <geom type="mesh" rgba="1 1 1 1" mesh="gripper_link"/>
                      <body name="r_gripper_finger_link" pos="0 0.015425 0" gravcomp="0">
                        <inertial pos="-0.01 0 0" mass="0.0798" diaginertia="0.000666667 0.000666667 0.000666667"/>
                        <joint name="robot:finger_joint1" pos="0 0 0" axis="0 1 0" type="slide" range="0 0.04" damping="100"/>
                        <geom pos="0 0.101425 0" type="mesh" rgba="0.356 0.361 0.376 1" mesh="r_gripper_finger_link"/>
                      </body>
                      <body name="l_gripper_finger_link" pos="0 -0.015425 0" gravcomp="0">
                        <inertial pos="-0.01 0 0" mass="0.0798" diaginertia="0.000666667 0.000666667 0.000666667"/>
                        <joint name="robot:finger_joint2" pos="0 0 0" axis="0 -1 0" type="slide" range="0 0.04" damping="100"/>
                        <geom pos="0 -0.101425 0" type="mesh" rgba="0.356 0.361 0.376 1" mesh="l_gripper_finger_link"/>
                      </body>
                      <!-- <site name="grip" pos="0 0 0" rgba="0 0 0 0" size="0.02 0.02 0.02"></site> -->
                      <site name="EEF" />
                    </body>
                    <!--  -->
                  </body>
                </body>
              </body>
            </body>
          </body>
        </body>
      </body>
      <body name="bellows_link" pos="0 0 0" gravcomp="0">
        <inertial pos="0.019132 0 -0.134862" quat="1 0 1.66507e-05 0" mass="0.169374" diaginertia="0.00331159 0.00174447 0.00169418"/>
        <joint name="bellows_joint" pos="0 0 0" axis="0 0 -1" type="slide" range="0 0.4"/>
        <geom type="mesh" rgba="0 0 0 1" mesh="bellows_link_collision"/>
      </body>
    </body>
  </body>

  <!-- Actuators -->

  <tendon>
    <fixed name="split">
      <joint joint="robot:finger_joint1" coef="0.5"/>
      <joint joint="robot:finger_joint2" coef="0.5"/>
    </fixed>
  </tendon>

  <equality>
    <joint joint1="robot:finger_joint1" joint2="robot:finger_joint1" solimp="0.95 0.99 0.001" solref="0.005 1"/>
  </equality>

  <actuator>
    <general class="panda" name="actuator1" joint="robot:joint1" gainprm="4500" biasprm="0 -4500 -450"/>
    <general class="panda" name="actuator2" joint="robot:joint2" gainprm="4500" biasprm="0 -4500 -450"
        ctrlrange="-1.7628 1.7628"/>
    <general class="panda" name="actuator3" joint="robot:joint3" gainprm="3500" biasprm="0 -3500 -350"/>
    <general class="panda" name="actuator4" joint="robot:joint4" gainprm="3500" biasprm="0 -3500 -350"
        ctrlrange="-3.0718 -0.0698"/>
    <general class="panda" name="actuator5" joint="robot:joint5" gainprm="2000" biasprm="0 -2000 -200"
        forcerange="-12 12"/>
    <general class="panda" name="actuator6" joint="robot:joint6" gainprm="2000" biasprm="0 -2000 -200"
        forcerange="-12 12" ctrlrange="-0.0175 3.7525"/>
    <general class="panda" name="actuator7" joint="robot:joint7" gainprm="2000" biasprm="0 -2000 -200"
        forcerange="-12 12"/>
    <general class="panda" name="actuator8" tendon="split" forcerange="-100 100" ctrlrange="0 255"
        gainprm="0.01568627451 0 0" biasprm="0 -100 -10"/>
  </actuator>
</mujoco>
